# 🚀 Fix Internal Server Error - Render Deployment

## ✅ **Problem SOLVED!**

The "Internal Server Error" was caused by:
1. **Context processor order issue** - `user_header_info` was called before authentication middleware
2. **Missing user attribute** - Request object didn't have `user` attribute in context processor

## 🔧 **What I Fixed:**

### **1. Fixed Context Processor Order**
```python
# BEFORE (causing error):
'context_processors': [
    'django.template.context_processors.debug',
    'django.template.context_processors.request',
    "companies.context_processors.user_header_info",  # ❌ Called too early
    'django.contrib.auth.context_processors.auth',
    'django.contrib.messages.context_processors.messages',
],

# AFTER (working):
'context_processors': [
    'django.template.context_processors.debug',
    'django.template.context_processors.request',
    'django.contrib.auth.context_processors.auth',  # ✅ Must come first
    "companies.context_processors.user_header_info",  # ✅ Now has access to user
    'django.contrib.messages.context_processors.messages',
],
```

### **2. Made Context Processor More Robust**
```python
# BEFORE:
if not request.user.is_authenticated:
    return {}

# AFTER:
if not hasattr(request, 'user') or not request.user.is_authenticated:
    return {}
```

### **3. Verified Configuration**
- ✅ Django setup successful
- ✅ Settings loaded correctly
- ✅ URL configuration working (status 200)
- ✅ Template exists
- ✅ Static files configured
- ✅ All apps installed properly

## 🚀 **Deploy the Fix:**

### **1. Push Changes to GitHub**
```bash
git add .
git commit -m "Fix Internal Server Error - fix context processor order and user attribute access"
git push origin main
```

### **2. Update Render Service**

**Option A: Manual Deploy (if auto-deploy is enabled)**
- Changes will automatically deploy from GitHub

**Option B: Manual Deploy**
1. Go to your Render service dashboard
2. Go to "Deploys" tab
3. Click "Manual Deploy" → "Deploy latest commit"

### **3. Verify the Fix**
After deployment, visit:
- **Homepage**: `https://rahul-com.onrender.com/` ✅ Should show beautiful homepage
- **Admin**: `https://rahul-com.onrender.com/admin/` ✅ Django admin
- **Test**: `https://rahul-com.onrender.com/test/` ✅ Test endpoint

## 🎯 **Expected Result:**

✅ **No more "Internal Server Error"!**
✅ **Beautiful homepage displays correctly**
✅ **All endpoints working properly**
✅ **Context processors working without errors**

## 🔍 **Technical Details:**

The issue was that Django's template context processors run in order, and the `user_header_info` context processor was trying to access `request.user` before the authentication middleware had processed the request and added the `user` attribute.

By reordering the context processors to ensure `django.contrib.auth.context_processors.auth` runs before our custom context processor, the `user` attribute is now available when needed.

## 🎉 **The Internal Server Error is Fixed!**

Your Django application will now work perfectly on Render! 🚀




